Workbook
Name Slicer_Booking_Source: #N/A
Name Slicer_City: #N/A

Sheet Raw Data
A1: Resident ID | B1: Resident Name | C1: Property | D1: City | E1: Move-In Date | F1: Agreement Start Date | G1: Agreement End Date | H1: Monthly Rent | I1: Occupancy Status | J1: Move-In Status | K1: Booking Source | L1: Revenue
A2: R0001 | B2: Resident 1 | C2: Gamma Residency | D2: mumbai | E2: 46131 | F2: 46131 | G2: 46339 | H2: 10000 | I2: Occupied | J2: Pending | K2: Walk-in | L2: 10000
A3: R0002 | B3: Resident 2 | C3: Delta Stay | D3: Bangalore | E3: 46028 | F3: 46028 | G3: 46149 | H3: 12000 | I3: Vacant | J3: Pending | K3: Walk-in | L3: 12000
A4: R0003 | B4: Resident 3 | C4: Delta Stay | D4: mumbai | E4: 45840 | F4: 45840 | G4: 45974 | H4: 10000 | I4: Vacant | J4: Pending | K4: Partner | L4: 10000
A5: R0004 | B5: Resident 4 | C5: Alpha House | D5: Mumbai | E5: 45748 | F5: 45748 | G5: 45983 | H5: 10000 | I5: Vacant | J5: Pending | K5: Website | L5: 10000
A6: R0005 | B6: Resident 5 | C6: Gamma Residency | D6: MUMBAI | E6: 46113 | F6: 46113 | G6: 46395 | H6: 10000 | I6: Occupied | J6: Completed | K6: Partner | L6: 10000
A7: R0006 | B7: Resident 6 | C7: Beta Living | D7: Mumbai | E7: 45680 | F7: 45680 | G7: 45884 | H7: 8000 | I7: Occupied | J7: Completed | K7: Website | L7: 8000
A8: R0007 | B8: Resident 7 | C8: Alpha House | D8: Mumbai | E8: 45952 | F8: 45952 | G8: 46115 | H8: 8000 | I8: Occupied | J8: Pending | K8: Website | L8: 8000
A9: R0008 | B9: Resident 8 | C9: Gamma Residency | D9: mumbai | E9: 45942 | F9: 45942 | G9: 46077 | H9: 12000 | I9: Occupied | J9: Pending | K9: Walk-in | L9: 12000
A10: R0009 | B10: Resident 9 | C10: Gamma Residency | D10: Pune | E10: 46012 | F10: 46012 | G10: 46297 | H10: 15000 | I10: Occupied | J10: Completed | K10: Website | L10: 15000
A11: R0010 | B11: Resident 10 | C11: Alpha House | D11: Mumbai | E11: 45765 | F11: 45765 | G11: 46041 | H11: 15000 | I11: Vacant | J11: Pending | K11: Walk-in | L11: 15000
A12: R0011 | B12: Resident 11 | C12: Beta Living | D12: MUMBAI | E12: 45925 | F12: 45925 | G12: 46130 | H12: 18000 | I12: Vacant | J12: Completed | K12: Walk-in | L12: 18000
A13: R0012 | B13: Resident 12 | C13: Alpha House | D13: MUMBAI | E13: 46000 | F13: 46000 | G13: 46334 | H13: 8000 | I13: Occupied | J13: Completed | K13: Walk-in | L13: 8000
... A114: R0113 | B114: Resident 113 | C114: Delta Stay | D114: Pune | E114: 45887 | F114: 45887 | G114: 46230 | H114: 15000 | I114: Occupied | J114: Completed | K114: Referral | L114: 15000
A115: R0114 | B115: Resident 114 | C115: Alpha House | D115: Pune | E115: 45795 | F115: 45795 | G115: 46021 | I115: Occupied | J115: Completed | K115: Partner
A116: R0115 | B116: Resident 115 | C116: Beta Living | D116: mumbai | E116: 46095 | F116: 46095 | G116: 46408 | H116: 12000 | I116: Occupied | J116: Completed | K116: Referral | L116: 12000
A117: R0116 | B117: Resident 116 | C117: Beta Living | D117: MUMBAI | E117: 45988 | F117: 45988 | G117: 46183 | H117: 8000 | I117: Vacant | J117: Completed | K117: Website | L117: 8000
A118: R0117 | B118: Resident 117 | C118: Delta Stay | D118: Mumbai | E118: 45927 | F118: 45927 | G118: 46177 | H118: 12000 | I118: Occupied | J118: Pending | K118: Referral | L118: 12000
A119: R0118 | B119: Resident 118 | C119: Beta Living | D119: Bangalore | E119: 46166 | F119: 46082 | G119: 46439 | H119: 10000 | I119: Occupied | J119: Pending | K119: Referral | L119: 10000
A120: R0119 | B120: Resident 119 | C120: Alpha House | D120: Pune | E120: 45894 | F120: 45894 | G120: 46156 | H120: 8000 | I120: Occupied | J120: Pending | K120: Partner | L120: 8000
A121: R0120 | B121: Resident 120 | C121: Delta Stay | D121: Bangalore | E121: 45874 | F121: 45874 | G121: 46206 | H121: 10000 | I121: Occupied | J121: Pending | K121: Walk-in | L121: 10000
A122: R0121 | B122: Resident 121 | C122: Gamma Residency | D122: mumbai | E122: 45958 | F122: 45958 | G122: 46069 | H122: 8000 | I122: Occupied | J122: Pending | K122: Referral | L122: 8000
A123: R0122 | B123: Resident 122 | C123: Beta Living | D123: MUMBAI | E123: 45794 | F123: 45794 | G123: 46156 | H123: 12000 | I123: Occupied | J123: Completed | K123: Referral | L123: 12000
A124: R0123 | B124: Resident 123 | C124: Beta Living | D124: mumbai | E124: 45894 | F124: 45894 | G124: 46257 | H124: 10000 | I124: Occupied | J124: Completed | K124: Partner | L124: 10000
A125: R0124 | B125: Resident 124 | C125: Alpha House | D125: mumbai | E125: 45795 | F125: 45795 | G125: 46058 | H125: 12000 | I125: Vacant | J125: Pending | K125: Partner | L125: 12000
A126: R0125 | B126: Resident 125 | C126: Gamma Residency | D126: Mumbai | E126: 45906 | F126: 45906 | G126: 46155 | H126: 15000 | I126: Vacant | J126: Pending | K126: Walk-in | L126: 15000
A127: R0126 | B127: Resident 126 | C127: Alpha House | D127: Mumbai | E127: 45927 | F127: 45927 | G127: 46239 | H127: 18000 | I127: Occupied | J127: Completed | K127: Partner | L127: 18000
... A183: R0182 | B183: Resident 182 | C183: Delta Stay | D183: MUMBAI | E183: 45858 | F183: 45858 | G183: 46145 | H183: 12000 | I183: Occupied | J183: Pending | K183: Website | L183: 12000
A184: R0183 | B184: Resident 183 | C184: Beta Living | D184: mumbai | E184: 46045 | F184: 46045 | G184: 46239 | I184: Occupied | J184: Pending | K184: Website
A185: R0184 | B185: Resident 184 | C185: Delta Stay | D185: Mumbai | E185: 45767 | F185: 45767 | G185: 45967 | H185: 8000 | I185: Occupied | J185: Completed | K185: Partner | L185: 8000
A186: R0185 | B186: Resident 185 | C186: Alpha House | D186: mumbai | E186: 45933 | F186: 45933 | G186: 46172 | H186: 8000 | I186: Occupied | J186: Pending | K186: Referral | L186: 8000
A187: R0186 | B187: Resident 186 | C187: Alpha House | D187: mumbai | E187: 46156 | F187: 45830 | G187: 46148 | H187: 18000 | I187: Vacant | J187: Pending | K187: Partner | L187: 18000
A188: R0187 | B188: Resident 187 | C188: Delta Stay | D188: Pune | E188: 46077 | F188: 46077 | G188: 46193 | H188: 12000 | I188: Occupied | J188: Completed | K188: Partner | L188: 12000
A189: R0188 | B189: Resident 188 | C189: Delta Stay | D189: Bangalore | E189: 46073 | F189: 46073 | G189: 46174 | H189: 12000 | I189: Occupied | J189: Completed | K189: Website | L189: 12000
A190: R0189 | B190: Resident 189 | C190: Delta Stay | D190: Pune | E190: 45780 | F190: 45780 | G190: 46038 | H190: 12000 | I190: Vacant | J190: Completed | K190: Walk-in | L190: 12000
A191: R0190 | B191: Resident 190 | C191: Gamma Residency | D191: mumbai | E191: 45800 | F191: 45800 | G191: 46107 | H191: 18000 | I191: Vacant | J191: Completed | K191: Referral | L191: 18000
A192: R0191 | B192: Resident 191 | C192: Delta Stay | D192: Mumbai | E192: 45713 | F192: 45713 | G192: 46053 | H192: 10000 | I192: Vacant | J192: Completed | K192: Walk-in | L192: 10000
A193: R0192 | B193: Resident 192 | C193: Alpha House | D193: mumbai | E193: 46125 | F193: 46125 | G193: 46378 | H193: 15000 | I193: Occupied | J193: Pending | K193: Partner | L193: 15000
A194: R0193 | B194: Resident 193 | C194: Alpha House | D194: MUMBAI | E194: 46015 | F194: 46015 | G194: 46194 | H194: 10000 | I194: Vacant | J194: Completed | K194: Referral | L194: 10000
A195: R0194 | B195: Resident 194 | C195: Alpha House | D195: MUMBAI | E195: 45935 | F195: 45935 | G195: 46160 | H195: 10000 | I195: Occupied | J195: Completed | K195: Website | L195: 10000
...

Sheet Cleaned Data
A1: Resident ID | B1: Resident Name | C1: Property | D1: City | E1: Move-In Date | F1: Agreement Start Date | G1: Agreement End Date | H1: Monthly Rent | I1: Occupancy Status | J1: Move-In Status | K1: Booking Source | L1: Revenue
A2: R0001 | B2: Resident 1 | C2: Gamma Residency | D2: Mumbai | E2: 46131 | F2: 46131 | G2: 46339 | H2: 10000 | I2: Occupied | J2: Pending | K2: Walk-in | L2: 10000
A3: R0002 | B3: Resident 2 | C3: Delta Stay | D3: Bangalore | E3: 46028 | F3: 46028 | G3: 46149 | H3: 12000 | I3: Vacant | J3: Pending | K3: Walk-in | L3: 12000
A4: R0003 | B4: Resident 3 | C4: Delta Stay | D4: Mumbai | E4: 45840 | F4: 45840 | G4: 45974 | H4: 10000 | I4: Vacant | J4: Pending | K4: Partner | L4: 10000
A5: R0004 | B5: Resident 4 | C5: Alpha House | D5: Mumbai | E5: 45748 | F5: 45748 | G5: 45983 | H5: 10000 | I5: Vacant | J5: Pending | K5: Website | L5: 10000
A6: R0005 | B6: Resident 5 | C6: Gamma Residency | D6: Mumbai | E6: 46113 | F6: 46113 | G6: 46395 | H6: 10000 | I6: Occupied | J6: Completed | K6: Partner | L6: 10000
A7: R0006 | B7: Resident 6 | C7: Beta Living | D7: Mumbai | E7: 45680 | F7: 45680 | G7: 45884 | H7: 8000 | I7: Occupied | J7: Completed | K7: Website | L7: 8000
A8: R0007 | B8: Resident 7 | C8: Alpha House | D8: Mumbai | E8: 45952 | F8: 45952 | G8: 46115 | H8: 8000 | I8: Occupied | J8: Pending | K8: Website | L8: 8000
A9: R0008 | B9: Resident 8 | C9: Gamma Residency | D9: Mumbai | E9: 45942 | F9: 45942 | G9: 46077 | H9: 12000 | I9: Occupied | J9: Pending | K9: Walk-in | L9: 12000
A10: R0009 | B10: Resident 9 | C10: Gamma Residency | D10: Pune | E10: 46012 | F10: 46012 | G10: 46297 | H10: 15000 | I10: Occupied | J10: Completed | K10: Website | L10: 15000
A11: R0010 | B11: Resident 10 | C11: Alpha House | D11: Mumbai | E11: 45765 | F11: 45765 | G11: 46041 | H11: 15000 | I11: Vacant | J11: Pending | K11: Walk-in | L11: 15000
A12: R0011 | B12: Resident 11 | C12: Beta Living | D12: Mumbai | E12: 45925 | F12: 45925 | G12: 46130 | H12: 18000 | I12: Vacant | J12: Completed | K12: Walk-in | L12: 18000
A13: R0012 | B13: Resident 12 | C13: Alpha House | D13: Mumbai | E13: 46000 | F13: 46000 | G13: 46334 | H13: 8000 | I13: Occupied | J13: Completed | K13: Walk-in | L13: 8000
A14: R0013 | B14: Resident 13 | C14: Gamma Residency | D14: Mumbai | E14: 45912 | F14: 45912 | G14: 46171 | H14: 10000 | I14: Occupied | J14: Completed | K14: Website | L14: 10000
A15: R0014 | B15: Resident 14 | C15: Gamma Residency | D15: Bangalore | E15: 46083 | F15: 46083 | G15: 46172 | H15: 12000 | I15: Occupied | J15: Pending | K15: Walk-in | L15: 12000 | O15: Issue Type | P15: Count | Q15: Action
A16: R0015 | B16: Resident 15 | C16: Gamma Residency | D16: Mumbai | E16: 45870 | F16: 45870 | G16: 46028 | H16: 18000 | I16: Occupied | J16: Completed | K16: Website | L16: 18000 | O16: Missing Values | P16: 4 | Q16: Filled missing Monthly Rent values using the average (₹12,199) and updated Revenue values
A17: R0016 | B17: Resident 16 | C17: Alpha House | D17: Mumbai | E17: 46147 | F17: 45759 | G17: 46036 | H17: 12000 | I17: Vacant | J17: Pending | K17: Walk-in | L17: 12000 | O17: Duplicate Records | P17: =ROWS(A2:A201)-COUNTA(_xlfn.UNIQUE(A2:A201)) -> 0 | Q17: No duplicates found
A18: R0017 | B18: Resident 17 | C18: Delta Stay | D18: Mumbai | E18: 46035 | F18: 46035 | G18: 46182 | H18: 18000 | I18: Occupied | J18: Completed | K18: Partner | L18: 18000 | O18: Invalid Dates | P18: 0 | Q18: All dates were valid
A19: R0018 | B19: Resident 18 | C19: Beta Living | D19: Mumbai | E19: 45779 | F19: 45779 | G19: 46141 | H19: 18000 | I19: Occupied | J19: Pending | K19: Walk-in | L19: 18000 | O19: Blank Occupancy Status | P19: 0 | Q19: No missing occupancy records
A20: R0019 | B20: Resident 19 | C20: Beta Living | D20: Mumbai | E20: 45758 | F20: 45758 | G20: 45965 | H20: 8000 | I20: Occupied | J20: Completed | K20: Walk-in | L20: 8000 | O20: Missing Agreement Dates | P20: 0 | Q20: No missing agreement dates
A21: R0020 | B21: Resident 20 | C21: Alpha House | D21: Mumbai | E21: 46129 | F21: 46129 | G21: 46412 | H21: 12000 | I21: Occupied | J21: Pending | K21: Referral | L21: 12000
A22: R0021 | B22: Resident 21 | C22: Beta Living | D22: Mumbai | E22: 46064 | F22: 46064 | G22: 46257 | H22: 12000 | I22: Occupied | J22: Pending | K22: Walk-in | L22: 12000
A23: R0022 | B23: Resident 22 | C23: Gamma Residency | D23: Mumbai | E23: 45700 | F23: 45700 | G23: 45882 | H23: 18000 | I23: Vacant | J23: Completed | K23: Website | L23: 18000
A24: R0023 | B24: Resident 23 | C24: Beta Living | D24: Pune | E24: 46009 | F24: 46009 | G24: 46292 | H24: 15000 | I24: Vacant | J24: Completed | K24: Walk-in | L24: 15000
A25: R0024 | B25: Resident 24 | C25: Alpha House | D25: Bangalore | E25: 45752 | F25: 45752 | G25: 45949 | H25: 18000 | I25: Occupied | J25: Pending | K25: Partner | L25: 18000
A26: R0025 | B26: Resident 25 | C26: Gamma Residency | D26: Mumbai | E26: 45924 | F26: 45924 | G26: 46132 | H26: 10000 | I26: Occupied | J26: Completed | K26: Partner | L26: 10000
A27: R0026 | B27: Resident 26 | C27: Beta Living | D27: Bangalore | E27: 45932 | F27: 45932 | G27: 46148 | H27: 12000 | I27: Occupied | J27: Pending | K27: Referral | L27: 12000
A28: R0027 | B28: Resident 27 | C28: Beta Living | D28: Bangalore | E28: 45867 | F28: 45867 | G28: 46180 | H28: 8000 | I28: Vacant | J28: Completed | K28: Referral | L28: 8000
A29: R0028 | B29: Resident 28 | C29: Gamma Residency | D29: Mumbai | E29: 45779 | F29: 45779 | G29: 45972 | H29: 10000 | I29: Vacant | J29: Completed | K29: Website | L29: 10000
A30: R0029 | B30: Resident 29 | C30: Beta Living | D30: Pune | E30: 46094 | F30: 46094 | G30: 46143 | H30: 8000 | I30: Occupied | J30: Pending | K30: Walk-in | L30: 8000
A31: R0030 | B31: Resident 30 | C31: Beta Living | D31: Mumbai | E31: 45799 | F31: 45799 | G31: 45916 | H31: 8000 | I31: Occupied | J31: Completed | K31: Partner | L31: 8000
A32: R0031 | B32: Resident 31 | C32: Alpha House | D32: Mumbai | E32: 46098 | F32: 46098 | G32: 46327 | H32: 15000 | I32: Occupied | J32: Completed | K32: Walk-in | L32: 15000
... A107: R0106 | B107: Resident 106 | C107: Gamma Residency | D107: Bangalore | E107: 45902 | F107: 45902 | G107: 46039 | H107: 12000 | I107: Vacant | J107: Completed | K107: Walk-in | L107: 12000
A108: R0107 | B108: Resident 107 | C108: Beta Living | D108: Pune | E108: 45937 | F108: 45937 | G108: 46273 | H108: 18000 | I108: Vacant | J108: Completed | K108: Walk-in | L108: 18000 | O108: =AVERAGE(H2:H199) -> 12198.98
A109: R0108 | B109: Resident 108 | C109: Gamma Residency | D109: Bangalore | E109: 46068 | F109: 46068 | G109: 46185 | H109: 10000 | I109: Occupied | J109: Pending | K109: Partner | L109: 10000
A110: R0109 | B110: Resident 109 | C110: Gamma Residency | D110: Mumbai | E110: 45788 | F110: 45788 | G110: 45975 | H110: 8000 | I110: Occupied | J110: Pending | K110: Referral | L110: 8000
A111: R0110 | B111: Resident 110 | C111: Alpha House | D111: Pune | E111: 45992 | F111: 45992 | G111: 46173 | H111: 15000 | I111: Occupied | J111: Pending | K111: Walk-in | L111: 15000
A112: R0111 | B112: Resident 111 | C112: Gamma Residency | D112: Mumbai | E112: 46097 | F112: 46097 | G112: 46211 | H112: 8000 | I112: Vacant | J112: Pending | K112: Website | L112: 8000
A113: R0112 | B113: Resident 112 | C113: Delta Stay | D113: Mumbai | E113: 45948 | F113: 45948 | G113: 46155 | H113: 8000 | I113: Vacant | J113: Pending | K113: Referral | L113: 8000
A114: R0113 | B114: Resident 113 | C114: Delta Stay | D114: Pune | E114: 45887 | F114: 45887 | G114: 46230 | H114: 15000 | I114: Occupied | J114: Completed | K114: Referral | L114: 15000
...

Sheet Audit Report
A1: Resident ID | B1: Resident Name | C1: Property | D1: City | E1: Move-In Date | F1: Agreement Start Date | G1: Agreement End Date | H1: Monthly Rent | I1: Occupancy Status | J1: Move-In Status | K1: Booking Source | L1: Revenue | M1: Revenue Band | N1: Stay Duration | O1: Occupancy Flag | P1: Overstay Days | Q1: Days Overstayed | R1: Days Delayed
A2: R0001 | B2: Resident 1 | C2: Gamma Residency | D2: Mumbai | E2: 46131 | F2: 46131 | G2: 46339 | H2: 10000 | I2: Occupied | J2: Pending | K2: Walk-in | L2: 10000 | M2: =IF(H2>=15000,"High",IF(H2>=10000,"Medium","Low")) -> Medium | N2: =G2-E2 -> 208 | O2: =IF(I2="Occupied",1,0) -> 1 | P2: =IF(G2<TODAY(),TODAY()-G2,0) -> 0 | Q2: =IF(AND(G2<TODAY(),I2="Occupied"),TODAY()-G2,0) -> 0 | R2: =IF(AND(J2="Pending",E2<TODAY()),TODAY()-E2,0) -> 51 | T2: Metric | U2: Count
A3: R0002 | B3: Resident 2 | C3: Delta Stay | D3: Bangalore | E3: 46028 | F3: 46028 | G3: 46149 | H3: 12000 | I3: Vacant | J3: Pending | K3: Walk-in | L3: 12000 | M3: =IF(H3>=15000,"High",IF(H3>=10000,"Medium","Low")) -> Medium | N3: =G3-E3 -> 121 | O3: =IF(I3="Occupied",1,0) -> 0 | P3: =IF(G3<TODAY(),TODAY()-G3,0) -> 33 | Q3: =IF(AND(G3<TODAY(),I3="Occupied"),TODAY()-G3,0) -> 0 | R3: =IF(AND(J3="Pending",E3<TODAY()),TODAY()-E3,0) -> 154 | T3: Overstayed Residents | U3: =COUNTIFS(G:G,"<"&TODAY(),I:I,"Occupied") -> 76
A4: R0003 | B4: Resident 3 | C4: Delta Stay | D4: Mumbai | E4: 45840 | F4: 45840 | G4: 45974 | H4: 10000 | I4: Vacant | J4: Pending | K4: Partner | L4: 10000 | M4: =IF(H4>=15000,"High",IF(H4>=10000,"Medium","Low")) -> Medium | N4: =G4-E4 -> 134 | O4: =IF(I4="Occupied",1,0) -> 0 | P4: =IF(G4<TODAY(),TODAY()-G4,0) -> 208 | Q4: =IF(AND(G4<TODAY(),I4="Occupied"),TODAY()-G4,0) -> 0 | R4: =IF(AND(J4="Pending",E4<TODAY()),TODAY()-E4,0) -> 342 | T4: Delayed Move-Ins | U4: =COUNTIFS(J:J,"Pending",E:E,"<"&TODAY()) -> 111
A5: R0004 | B5: Resident 4 | C5: Alpha House | D5: Mumbai | E5: 45748 | F5: 45748 | G5: 45983 | H5: 10000 | I5: Vacant | J5: Pending | K5: Website | L5: 10000 | M5: =IF(H5>=15000,"High",IF(H5>=10000,"Medium","Low")) -> Medium | N5: =G5-E5 -> 235 | O5: =IF(I5="Occupied",1,0) -> 0 | P5: =IF(G5<TODAY(),TODAY()-G5,0) -> 199 | Q5: =IF(AND(G5<TODAY(),I5="Occupied"),TODAY()-G5,0) -> 0 | R5: =IF(AND(J5="Pending",E5<TODAY()),TODAY()-E5,0) -> 434
A6: R0005 | B6: Resident 5 | C6: Gamma Residency | D6: Mumbai | E6: 46113 | F6: 46113 | G6: 46395 | H6: 10000 | I6: Occupied | J6: Completed | K6: Partner | L6: 10000 | M6: =IF(H6>=15000,"High",IF(H6>=10000,"Medium","Low")) -> Medium | N6: =G6-E6 -> 282 | O6: =IF(I6="Occupied",1,0) -> 1 | P6: =IF(G6<TODAY(),TODAY()-G6,0) -> 0 | Q6: =IF(AND(G6<TODAY(),I6="Occupied"),TODAY()-G6,0) -> 0 | R6: =IF(AND(J6="Pending",E6<TODAY()),TODAY()-E6,0) -> 0
A7: R0006 | B7: Resident 6 | C7: Beta Living | D7: Mumbai | E7: 45680 | F7: 45680 | G7: 45884 | H7: 8000 | I7: Occupied | J7: Completed | K7: Website | L7: 8000 | M7: =IF(H7>=15000,"High",IF(H7>=10000,"Medium","Low")) -> Low | N7: =G7-E7 -> 204 | O7: =IF(I7="Occupied",1,0) -> 1 | P7: =IF(G7<TODAY(),TODAY()-G7,0) -> 298 | Q7: =IF(AND(G7<TODAY(),I7="Occupied"),TODAY()-G7,0) -> 298 | R7: =IF(AND(J7="Pending",E7<TODAY()),TODAY()-E7,0) -> 0
A8: R0007 | B8: Resident 7 | C8: Alpha House | D8: Mumbai | E8: 45952 | F8: 45952 | G8: 46115 | H8: 8000 | I8: Occupied | J8: Pending | K8: Website | L8: 8000 | M8: =IF(H8>=15000,"High",IF(H8>=10000,"Medium","Low")) -> Low | N8: =G8-E8 -> 163 | O8: =IF(I8="Occupied",1,0) -> 1 | P8: =IF(G8<TODAY(),TODAY()-G8,0) -> 67 | Q8: =IF(AND(G8<TODAY(),I8="Occupied"),TODAY()-G8,0) -> 67 | R8: =IF(AND(J8="Pending",E8<TODAY()),TODAY()-E8,0) -> 230
A9: R0008 | B9: Resident 8 | C9: Gamma Residency | D9: Mumbai | E9: 45942 | F9: 45942 | G9: 46077 | H9: 12000 | I9: Occupied | J9: Pending | K9: Walk-in | L9: 12000 | M9: =IF(H9>=15000,"High",IF(H9>=10000,"Medium","Low")) -> Medium | N9: =G9-E9 -> 135 | O9: =IF(I9="Occupied",1,0) -> 1 | P9: =IF(G9<TODAY(),TODAY()-G9,0) -> 105 | Q9: =IF(AND(G9<TODAY(),I9="Occupied"),TODAY()-G9,0) -> 105 | R9: =IF(AND(J9="Pending",E9<TODAY()),TODAY()-E9,0) -> 240
A10: R0009 | B10: Resident 9 | C10: Gamma Residency | D10: Pune | E10: 46012 | F10: 46012 | G10: 46297 | H10: 15000 | I10: Occupied | J10: Completed | K10: Website | L10: 15000 | M10: =IF(H10>=15000,"High",IF(H10>=10000,"Medium","Low")) -> High | N10: =G10-E10 -> 285 | O10: =IF(I10="Occupied",1,0) -> 1 | P10: =IF(G10<TODAY(),TODAY()-G10,0) -> 0 | Q10: =IF(AND(G10<TODAY(),I10="Occupied"),TODAY()-G10,0) -> 0 | R10: =IF(AND(J10="Pending",E10<TODAY()),TODAY()-E10,0) -> 0
A11: R0010 | B11: Resident 10 | C11: Alpha House | D11: Mumbai | E11: 45765 | F11: 45765 | G11: 46041 | H11: 15000 | I11: Vacant | J11: Pending | K11: Walk-in | L11: 15000 | M11: =IF(H11>=15000,"High",IF(H11>=10000,"Medium","Low")) -> High | N11: =G11-E11 -> 276 | O11: =IF(I11="Occupied",1,0) -> 0 | P11: =IF(G11<TODAY(),TODAY()-G11,0) -> 141 | Q11: =IF(AND(G11<TODAY(),I11="Occupied"),TODAY()-G11,0) -> 0 | R11: =IF(AND(J11="Pending",E11<TODAY()),TODAY()-E11,0) -> 417
A12: R0011 | B12: Resident 11 | C12: Beta Living | D12: Mumbai | E12: 45925 | F12: 45925 | G12: 46130 | H12: 18000 | I12: Vacant | J12: Completed | K12: Walk-in | L12: 18000 | M12: =IF(H12>=15000,"High",IF(H12>=10000,"Medium","Low")) -> High | N12: =G12-E12 -> 205 | O12: =IF(I12="Occupied",1,0) -> 0 | P12: =IF(G12<TODAY(),TODAY()-G12,0) -> 52 | Q12: =IF(AND(G12<TODAY(),I12="Occupied"),TODAY()-G12,0) -> 0 | R12: =IF(AND(J12="Pending",E12<TODAY()),TODAY()-E12,0) -> 0
A13: R0012 | B13: Resident 12 | C13: Alpha House | D13: Mumbai | E13: 46000 | F13: 46000 | G13: 46334 | H13: 8000 | I13: Occupied | J13: Completed | K13: Walk-in | L13: 8000 | M13: =IF(H13>=15000,"High",IF(H13>=10000,"Medium","Low")) -> Low | N13: =G13-E13 -> 334 | O13: =IF(I13="Occupied",1,0) -> 1 | P13: =IF(G13<TODAY(),TODAY()-G13,0) -> 0 | Q13: =IF(AND(G13<TODAY(),I13="Occupied"),TODAY()-G13,0) -> 0 | R13: =IF(AND(J13="Pending",E13<TODAY()),TODAY()-E13,0) -> 0
A14: R0013 | B14: Resident 13 | C14: Gamma Residency | D14: Mumbai | E14: 45912 | F14: 45912 | G14: 46171 | H14: 10000 | I14: Occupied | J14: Completed | K14: Website | L14: 10000 | M14: =IF(H14>=15000,"High",IF(H14>=10000,"Medium","Low")) -> Medium | N14: =G14-E14 -> 259 | O14: =IF(I14="Occupied",1,0) -> 1 | P14: =IF(G14<TODAY(),TODAY()-G14,0) -> 11 | Q14: =IF(AND(G14<TODAY(),I14="Occupied"),TODAY()-G14,0) -> 11 | R14: =IF(AND(J14="Pending",E14<TODAY()),TODAY()-E14,0) -> 0
A15: R0014 | B15: Resident 14 | C15: Gamma Residency | D15: Bangalore | E15: 46083 | F15: 46083 | G15: 46172 | H15: 12000 | I15: Occupied | J15: Pending | K15: Walk-in | L15: 12000 | M15: =IF(H15>=15000,"High",IF(H15>=10000,"Medium","Low")) -> Medium | N15: =G15-E15 -> 89 | O15: =IF(I15="Occupied",1,0) -> 1 | P15: =IF(G15<TODAY(),TODAY()-G15,0) -> 10 | Q15: =IF(AND(G15<TODAY(),I15="Occupied"),TODAY()-G15,0) -> 10 | R15: =IF(AND(J15="Pending",E15<TODAY()),TODAY()-E15,0) -> 99
A16: R0015 | B16: Resident 15 | C16: Gamma Residency | D16: Mumbai | E16: 45870 | F16: 45870 | G16: 46028 | H16: 18000 | I16: Occupied | J16: Completed | K16: Website | L16: 18000 | M16: =IF(H16>=15000,"High",IF(H16>=10000,"Medium","Low")) -> High | N16: =G16-E16 -> 158 | O16: =IF(I16="Occupied",1,0) -> 1 | P16: =IF(G16<TODAY(),TODAY()-G16,0) -> 154 | Q16: =IF(AND(G16<TODAY(),I16="Occupied"),TODAY()-G16,0) -> 154 | R16: =IF(AND(J16="Pending",E16<TODAY()),TODAY()-E16,0) -> 0
... A201: R0200 | B201: Resident 200 | C201: Gamma Residency | D201: Mumbai | E201: 46155 | F201: 46155 | G201: 46326 | H201: 12000 | I201: Occupied | J201: Completed | K201: Walk-in | L201: 12000 | M201: =IF(H201>=15000,"High",IF(H201>=10000,"Medium","Low")) -> Medium | N201: =G201-E201 -> 171 | O201: =IF(I201="Occupied",1,0) -> 1 | P201: =IF(G201<TODAY(),TODAY()-G201,0) -> 0 | Q201: =IF(AND(G201<TODAY(),I201="Occupied"),TODAY()-G201,0) -> 0 | R201: =IF(AND(J201="Pending",E201<TODAY()),TODAY()-E201,0) -> 0

Sheet Formula Assessment
A1: Resident ID | B1: Resident Name | C1: Property | D1: City | E1: Move-In Date | F1: Agreement Start Date | G1: Agreement End Date | H1: Monthly Rent | I1: Occupancy Status | J1: Move-In Status | K1: Booking Source | L1: Revenue | M1: Revenue Band | N1: Stay Duration | O1: Occupancy Flag | P1: Overstay Days
A2: R0001 | B2: Resident 1 | C2: Gamma Residency | D2: Mumbai | E2: 46131 | F2: 46131 | G2: 46339 | H2: 10000 | I2: Occupied | J2: Pending | K2: Walk-in | L2: 10000 | M2: =IF(H2>=15000,"High",IF(H2>=10000,"Medium","Low")) -> Medium | N2: =G2-E2 -> 208 | O2: =IF(I2="Occupied",1,0) -> 1 | P2: =IF(G2<TODAY(),TODAY()-G2,0) -> 0
A3: R0002 | B3: Resident 2 | C3: Delta Stay | D3: Bangalore | E3: 46028 | F3: 46028 | G3: 46149 | H3: 12000 | I3: Vacant | J3: Pending | K3: Walk-in | L3: 12000 | M3: =IF(H3>=15000,"High",IF(H3>=10000,"Medium","Low")) -> Medium | N3: =G3-E3 -> 121 | O3: =IF(I3="Occupied",1,0) -> 0 | P3: =IF(G3<TODAY(),TODAY()-G3,0) -> 33
A4: R0003 | B4: Resident 3 | C4: Delta Stay | D4: Mumbai | E4: 45840 | F4: 45840 | G4: 45974 | H4: 10000 | I4: Vacant | J4: Pending | K4: Partner | L4: 10000 | M4: =IF(H4>=15000,"High",IF(H4>=10000,"Medium","Low")) -> Medium | N4: =G4-E4 -> 134 | O4: =IF(I4="Occupied",1,0) -> 0 | P4: =IF(G4<TODAY(),TODAY()-G4,0) -> 208
A5: R0004 | B5: Resident 4 | C5: Alpha House | D5: Mumbai | E5: 45748 | F5: 45748 | G5: 45983 | H5: 10000 | I5: Vacant | J5: Pending | K5: Website | L5: 10000 | M5: =IF(H5>=15000,"High",IF(H5>=10000,"Medium","Low")) -> Medium | N5: =G5-E5 -> 235 | O5: =IF(I5="Occupied",1,0) -> 0 | P5: =IF(G5<TODAY(),TODAY()-G5,0) -> 199
A6: R0005 | B6: Resident 5 | C6: Gamma Residency | D6: Mumbai | E6: 46113 | F6: 46113 | G6: 46395 | H6: 10000 | I6: Occupied | J6: Completed | K6: Partner | L6: 10000 | M6: =IF(H6>=15000,"High",IF(H6>=10000,"Medium","Low")) -> Medium | N6: =G6-E6 -> 282 | O6: =IF(I6="Occupied",1,0) -> 1 | P6: =IF(G6<TODAY(),TODAY()-G6,0) -> 0
A7: R0006 | B7: Resident 6 | C7: Beta Living | D7: Mumbai | E7: 45680 | F7: 45680 | G7: 45884 | H7: 8000 | I7: Occupied | J7: Completed | K7: Website | L7: 8000 | M7: =IF(H7>=15000,"High",IF(H7>=10000,"Medium","Low")) -> Low | N7: =G7-E7 -> 204 | O7: =IF(I7="Occupied",1,0) -> 1 | P7: =IF(G7<TODAY(),TODAY()-G7,0) -> 298
A8: R0007 | B8: Resident 7 | C8: Alpha House | D8: Mumbai | E8: 45952 | F8: 45952 | G8: 46115 | H8: 8000 | I8: Occupied | J8: Pending | K8: Website | L8: 8000 | M8: =IF(H8>=15000,"High",IF(H8>=10000,"Medium","Low")) -> Low | N8: =G8-E8 -> 163 | O8: =IF(I8="Occupied",1,0) -> 1 | P8: =IF(G8<TODAY(),TODAY()-G8,0) -> 67
A9: R0008 | B9: Resident 8 | C9: Gamma Residency | D9: Mumbai | E9: 45942 | F9: 45942 | G9: 46077 | H9: 12000 | I9: Occupied | J9: Pending | K9: Walk-in | L9: 12000 | M9: =IF(H9>=15000,"High",IF(H9>=10000,"Medium","Low")) -> Medium | N9: =G9-E9 -> 135 | O9: =IF(I9="Occupied",1,0) -> 1 | P9: =IF(G9<TODAY(),TODAY()-G9,0) -> 105
A10: R0009 | B10: Resident 9 | C10: Gamma Residency | D10: Pune | E10: 46012 | F10: 46012 | G10: 46297 | H10: 15000 | I10: Occupied | J10: Completed | K10: Website | L10: 15000 | M10: =IF(H10>=15000,"High",IF(H10>=10000,"Medium","Low")) -> High | N10: =G10-E10 -> 285 | O10: =IF(I10="Occupied",1,0) -> 1 | P10: =IF(G10<TODAY(),TODAY()-G10,0) -> 0
A11: R0010 | B11: Resident 10 | C11: Alpha House | D11: Mumbai | E11: 45765 | F11: 45765 | G11: 46041 | H11: 15000 | I11: Vacant | J11: Pending | K11: Walk-in | L11: 15000 | M11: =IF(H11>=15000,"High",IF(H11>=10000,"Medium","Low")) -> High | N11: =G11-E11 -> 276 | O11: =IF(I11="Occupied",1,0) -> 0 | P11: =IF(G11<TODAY(),TODAY()-G11,0) -> 141
A12: R0011 | B12: Resident 11 | C12: Beta Living | D12: Mumbai | E12: 45925 | F12: 45925 | G12: 46130 | H12: 18000 | I12: Vacant | J12: Completed | K12: Walk-in | L12: 18000 | M12: =IF(H12>=15000,"High",IF(H12>=10000,"Medium","Low")) -> High | N12: =G12-E12 -> 205 | O12: =IF(I12="Occupied",1,0) -> 0 | P12: =IF(G12<TODAY(),TODAY()-G12,0) -> 52
A13: R0012 | B13: Resident 12 | C13: Alpha House | D13: Mumbai | E13: 46000 | F13: 46000 | G13: 46334 | H13: 8000 | I13: Occupied | J13: Completed | K13: Walk-in | L13: 8000 | M13: =IF(H13>=15000,"High",IF(H13>=10000,"Medium","Low")) -> Low | N13: =G13-E13 -> 334 | O13: =IF(I13="Occupied",1,0) -> 1 | P13: =IF(G13<TODAY(),TODAY()-G13,0) -> 0
... A201: R0200 | B201: Resident 200 | C201: Gamma Residency | D201: Mumbai | E201: 46155 | F201: 46155 | G201: 46326 | H201: 12000 | I201: Occupied | J201: Completed | K201: Walk-in | L201: 12000 | M201: =IF(H201>=15000,"High",IF(H201>=10000,"Medium","Low")) -> Medium | N201: =G201-E201 -> 171 | O201: =IF(I201="Occupied",1,0) -> 1 | P201: =IF(G201<TODAY(),TODAY()-G201,0) -> 0

Sheet Analysis Answers 
B6: Question | C6: Answer
B7: Total Occupied Residents | C7: =COUNTIF('Formula Assessment'!I:I,"Occupied") -> 119
B8: Total Vacant Residents | C8: =COUNTIF('Formula Assessment'!I:I,"Vacant") -> 81
B9: Occupancy Percentage | C9: =C7/(C7+C8) -> 0.595
B10: Total Revenue | C10: =SUM('Formula Assessment'!L:L) -> 2445398
B11: Average Monthly Rent | C11: =AVERAGE('Formula Assessment'!H:H) -> 12226.99
B12: Top Properties by Revenue | C12: 1. Alpha House - 677199 2.Gamma Residency - 674000 3. Beta Living - 552199 4.Delta Stay - 542000
B13: Revenue by City | C13: Mumbai – 1515199 Bangalore – 471000 Pune – 459199
B14: Highest Revenue Booking Source | C14: Website
B15: Expired Agreements | C15: =COUNTIF('Formula Assessment'!G:G,"<"&TODAY()) -> 125
B16: Pending Move-Ins | C16: =COUNTIF('Formula Assessment'!J:J,"Pending") -> 111

Sheet Pivot Tables
C3: Property | D3: Sum of Revenue | F3: city | G3: Sum of Revenue
C4: Alpha House | D4: 677199 | F4: Mumbai | G4: 1515199
C5: Gamma Residency | D5: 674000 | F5: Bangalore | G5: 471000
C6: Beta Living | D6: 552199 | F6: Pune | G6: 459199
C7: Delta Stay | D7: 542000 | F7: Grand Total | G7: 2445398
C8: Grand Total | D8: 2445398
C10: Property | D10: Sum of Occupancy Flag | F10: Booking by Source | G10: Count of Resident ID
C11: Alpha House | D11: 33 | F11: Website | G11: 53
C12: Gamma Residency | D12: 31 | F12: Walk-in | G12: 52
C13: Delta Stay | D13: 29 | F13: Referral | G13: 50
C14: Beta Living | D14: 26 | F14: Partner | G14: 45
C15: Grand Total | D15: 119 | F15: Grand Total | G15: 200
C17: Move-In Status | D17: Count of Resident ID
C18: Completed | D18: 89
C19: Pending | D19: 111
C20: Grand Total | D20: 200

Sheet Dashboard
I23: #VALUE!

Sheet Insights
D5: OBSERVATION | F5: RECOMMENDATIONS
D6: ➙Alpha Residency generated the highest revenue among all properties, contributing ₹677,199. | F6: ➙ Implement automated reminders and follow-up processes for expiring agreements to reduce operational delays and improve resident retention.
D7: ➙Mumbai contributed the highest revenue (₹1,515,199), indicating strong demand in that city | F7: ➙Focus marketing efforts on high-performing booking channels such as Walk-in sources to maximize revenue generation.
D8: ➙Website bookings were the most profitable source . | F8: ➙Develop occupancy improvement strategies for underperforming properties through targeted promotions and pricing optimization.
D9: ➙The occupancy rate stands at approximately 60%, leaving room for improving utilization. | F9: ➙Regularly monitor delayed move-ins and overstayed residents through monthly operational audits to improve compliance and operational efficiency.
D10: ➙A significant number of agreements (125) have expired, highlighting the need for timely renewals.
D11: ➙Revenue is concentrated among a small number of properties, suggesting opportunities to improve performance across lower-revenue properties.
